<?xml version="1.0" ?>
<robot name="agribot" xmlns:xacro="http://www.ros.org/wiki/xacro">

<xacro:include filename="$(find agribot_description)/urdf/materials.xacro" />
<!--<xacro:include filename="$(find agribot_description)/urdf/agribot.trans" />-->
<xacro:include filename="$(find agribot_description)/gazebo/agribot_materials.gazebo" />
<xacro:include filename="$(find agribot_description)/gazebo/agribot_physics.gazebo" />
<xacro:include filename="$(find agribot_description)/gazebo/agribot_plugins.gazebo" />

<link name="base_link">
  <inertial>
    <origin xyz="9.261460023280907e-14 -0.0004240458420922852 0.019966170865145186" rpy="0 0 0"/>
    <mass value="9.511196180493643"/>
    <inertia ixx="0.033149" iyy="0.019055" izz="0.049585" ixy="0.0" iyz="-3.1e-05" ixz="0.0"/>
  </inertial>
  <visual>
    <origin xyz="0 0 0" rpy="0 0 0"/>
    <geometry>
      <mesh filename="package://agribot_description/meshes/base_link.stl" scale="0.001 0.001 0.001"/>
    </geometry>
    <material name="silver"/>
  </visual>
  <collision>
    <origin xyz="0 0 0" rpy="0 0 0"/>
    <geometry>
      <mesh filename="package://agribot_description/meshes/base_link.stl" scale="0.001 0.001 0.001"/>
    </geometry>
  </collision>
</link>

<link name="lidar_1">
  <inertial>
    <origin xyz="7.394185271433195e-18 6.938893903907228e-18 0.00998815108449349" rpy="0 0 0"/>
    <mass value="0.15086883195275047"/>
    <inertia ixx="1.7e-05" iyy="1.7e-05" izz="2.3e-05" ixy="0.0" iyz="-0.0" ixz="0.0"/>
  </inertial>
  <visual>
    <origin xyz="-0.0 0.06 -0.045" rpy="0 0 0"/>
    <geometry>
      <mesh filename="package://agribot_description/meshes/lidar_1.stl" scale="0.001 0.001 0.001"/>
    </geometry>
    <material name="silver"/>
  </visual>
  <collision>
    <origin xyz="-0.0 0.06 -0.045" rpy="0 0 0"/>
    <geometry>
      <mesh filename="package://agribot_description/meshes/lidar_1.stl" scale="0.001 0.001 0.001"/>
    </geometry>
  </collision>
</link>

<link name="left_wheel_1">
  <inertial>
    <origin xyz="-0.009999999999999995 0.0 0.0" rpy="0 0 0"/>
    <mass value="0.789168074581756"/>
    <inertia ixx="0.000631" iyy="0.000342" izz="0.000342" ixy="0.0" iyz="0.0" ixz="0.0"/>
  </inertial>
  <visual>
    <origin xyz="0.085 -0.09 -0.02" rpy="0 0 0"/>
    <geometry>
      <mesh filename="package://agribot_description/meshes/left_wheel_1.stl" scale="0.001 0.001 0.001"/>
    </geometry>
    <material name="silver"/>
  </visual>
  <collision>
    <origin xyz="0.085 -0.09 -0.02" rpy="0 0 0"/>
    <geometry>
      <mesh filename="package://agribot_description/meshes/left_wheel_1.stl" scale="0.001 0.001 0.001"/>
    </geometry>
  </collision>
</link>

<link name="right_wheel_1">
  <inertial>
    <origin xyz="0.009999999999999995 0.0 0.0" rpy="0 0 0"/>
    <mass value="0.789168074581756"/>
    <inertia ixx="0.000631" iyy="0.000342" izz="0.000342" ixy="0.0" iyz="0.0" ixz="0.0"/>
  </inertial>
  <visual>
    <origin xyz="-0.085 -0.09 -0.02" rpy="0 0 0"/>
    <geometry>
      <mesh filename="package://agribot_description/meshes/right_wheel_1.stl" scale="0.001 0.001 0.001"/>
    </geometry>
    <material name="silver"/>
  </visual>
  <collision>
    <origin xyz="-0.085 -0.09 -0.02" rpy="0 0 0"/>
    <geometry>
      <mesh filename="package://agribot_description/meshes/right_wheel_1.stl" scale="0.001 0.001 0.001"/>
    </geometry>
  </collision>
</link>

<joint name="Rigid_1" type="fixed">
  <origin xyz="0.0 -0.06 0.045" rpy="0 0 0"/>
  <parent link="base_link"/>
  <child link="lidar_1"/>
</joint>

<joint name="Revolute_2" type="continuous">
  <origin xyz="-0.085 0.09 0.02" rpy="0 0 0"/>
  <parent link="base_link"/>
  <child link="left_wheel_1"/>
  <axis xyz="-1.0 0.0 0.0"/>
</joint>

<joint name="Revolute_3" type="continuous">
  <origin xyz="0.085 0.09 0.02" rpy="0 0 0"/>
  <parent link="base_link"/>
  <child link="right_wheel_1"/>
  <axis xyz="1.0 0.0 0.0"/>
</joint>

</robot>
